<?xml version="1.0"?>
<sdf version='1.4'>
    <model name="my_robot">
        <static>false</static>
        <link name='chassis'>  
            <pose>0 0 .1 0 0 0</pose>  
            <collision name='collision_chassis'>  
                <geometry>  
                    <box>  
                        <size>.4 .2 .1</size>  
                    </box>  
                </geometry>  
                <surface>
                    <mass>10</mass>
                </surface>
            </collision>  
              
            <visual name='visual_chassis'>  
                <geometry>  
                    <box>  
                        <size>.4 .2 .1</size>  
                    </box>  
                </geometry>  
            </visual>  

            <collision name='caster_collision'>
            <pose>-0.15 0 -0.05 0 0 0</pose>
            <geometry>
                <sphere>
                    <radius>.05</radius>
                </sphere>
            </geometry>
            <surface>
                <mass>10</mass>
            </surface>
            </collision>
            
            <visual name='caster_visual'>
                <pose>-0.15 0 -0.05 0 0 0</pose>
                <geometry>
                    <sphere>
                        <radius>.05</radius>
                    </sphere>
                </geometry>
            </visual>
        </link>

        <link name="laser_frame">
            <pose>0 0 .15 0 0 0</pose>
            
            <!-- Add a mesh to make it more visually appealing -->
            <visual name="visual-laser">
              <geometry>
                <cylinder>  
                    <radius>.025</radius>  
                    <length>.025</length>  
                </cylinder> 
              </geometry>
            </visual>
            
            <!-- Collision properties of the base of the laser range finder-->
            <collision name="collision-laser">
              <geometry>
                <cylinder>  
                    <radius>.025</radius>  
                    <length>.025</length>  
                </cylinder> 
              </geometry>
            </collision>

            <sensor name="laser" type="ray">
                <pose>0 0 .15 0 0 0</pose>
                <ray>
                    <scan>
                    <horizontal>
                        <samples>360</samples>
                        <resolution>1</resolution>
                        <min_angle>-3.14</min_angle>
                        <max_angle>3.14</max_angle>
                    </horizontal>
                    </scan>
                    <range>
                    <min>0.08</min>
                    <max>10</max>
                    <resolution>0.05</resolution>
                    </range>
                </ray>
                <always_on>1</always_on>
                <update_rate>10</update_rate>
                <visualize>true</visualize>

                <plugin name='laser' filename='libgazebo_ros_ray_sensor.so'>
                    <ros>
                        <remapping>~/out:=/scan</remapping>
                    </ros>
                    <output_type>sensor_msgs/LaserScan</output_type>
                    <frame_name>laser_frame</frame_name>
                    <robot_base_frame>base_footprint</robot_base_frame>
                </plugin>
            </sensor>
        </link>

        <link name="left_wheel">  
            <pose>0.1 0.13 0.1 0 1.5707 1.5707</pose>  
            <collision name="collision_left">  
                <geometry>  
                    <cylinder>  
                        <radius>.1</radius>  
                        <length>.05</length>  
                    </cylinder>  
                </geometry> 
                <surface>
                    <friction>
                        <ode>
                            <mu>1</mu>
                            <mu2>1</mu2>
                            <slip1>0</slip1>
                            <slip2>0</slip2>
                        </ode>
                    </friction>
                </surface> 
            </collision>  
            <visual name="visual_left">  
                <geometry>  
                    <cylinder>  
                        <radius>.1</radius>  
                        <length>.05</length>  
                    </cylinder>  
                </geometry>  
            </visual>  
        </link>

        <link name="right_wheel">  
            <pose>0.1 -0.13 0.1 0 1.5707 1.5707</pose>  
            <collision name="collision_right">  
                <geometry>  
                    <cylinder>  
                        <radius>.1</radius>  
                        <length>.05</length>  
                    </cylinder>  
                </geometry>  
                <surface>
                    <friction>
                        <ode>
                            <mu>1</mu>
                            <mu2>1</mu2>
                            <slip1>0</slip1>
                            <slip2>0</slip2>
                        </ode>
                    </friction>
                </surface> 
            </collision>  
            <visual name="visual_right">  
                <geometry>  
                    <cylinder>  
                        <radius>.1</radius>  
                        <length>.05</length>  
                    </cylinder>  
                </geometry>  
            </visual>  
        </link>

        <joint type="revolute" name="left_wheel_hinge">  
            <pose>0 0 -0.03 0 0 0</pose>  
            <child>left_wheel</child>  
            <parent>chassis</parent>  
            <axis>  
                <xyz>0 1 0</xyz>  
            </axis>  
        </joint>  
          
        <joint type="revolute" name="right_wheel_hinge">  
            <pose>0 0 0.03 0 0 0</pose>  
            <child>right_wheel</child>  
            <parent>chassis</parent>  
            <axis>  
                <xyz>0 1 0</xyz>  
            </axis>  
        </joint>

        <joint type="fixed" name="laser_joint">
            <child>laser_frame</child>
            <parent>chassis</parent>
        </joint>

        

        <!-- Controls the differential drive robot -->
       <plugin name='diff_drive' filename='libgazebo_ros_diff_drive.so'>
        <ros>
          <remapping>cmd_vel:=cmd_vel</remapping>
          <remapping>odom:=odom</remapping>
        </ros>

        <!-- wheels -->
        <left_joint>left_wheel_hinge</left_joint>
        <right_joint>right_wheel_hinge</right_joint>

        <!-- kinematics -->
        <wheel_separation>0.26</wheel_separation>
        <wheel_diameter>0.2</wheel_diameter>

        <!-- limits -->
        <max_wheel_torque>10</max_wheel_torque>
        <max_wheel_acceleration>0.5</max_wheel_acceleration>

        <!-- output -->
        <publish_odom>true</publish_odom>
        <publish_odom_tf>true</publish_odom_tf>
        <publish_wheel_tf>true</publish_wheel_tf>

        <odometry_frame>odom</odometry_frame>
        <robot_base_frame>base_footprint</robot_base_frame>
      </plugin>      

    </model>
</sdf>